Time slot   0
ld_routine
Time slot   1
	Loaded a process at input/proc/p0s, PID: 1 PRIO: 130
	CPU 3: Dispatched process  1
liballoc:184
print_pgtbl:
 PGD=7f0fa4007770 P4D=7f0fa0000bd0 PUD=7f0fa0001be0 PMD=7f0fa0002bf0
Time slot   2
	Loaded a process at input/proc/m0s, PID: 2 PRIO: 120
Time slot   3
	CPU 2: Dispatched process  2
liballoc:184
print_pgtbl:
 PGD=7f0fa400a220 P4D=7f0f98000bd0 PUD=7f0f98001be0 PMD=7f0f98002bf0
	CPU 3: Put process  1 to run queue
	CPU 3: Dispatched process  1
liballoc:184
print_pgtbl:
 PGD=7f0fa4007770 P4D=7f0fa0000bd0 PUD=7f0fa0001be0 PMD=7f0fa0002bf0
Time slot   4
liballoc:184
print_pgtbl:
 PGD=7f0fa400a220 P4D=7f0f98000bd0 PUD=7f0f98001be0 PMD=7f0f98002bf0
libfree:209
print_pgtbl:
 PGD=7f0fa4007770 P4D=7f0fa0000bd0 PUD=7f0fa0001be0 PMD=7f0fa0002bf0
	Loaded a process at input/proc/s3, PID: 3 PRIO: 39
	Loaded a process at input/proc/s0, PID: 4 PRIO: 38
	CPU 2: Put process  2 to run queue
	CPU 2: Dispatched process  4
	CPU 1: Dispatched process  3
	CPU 3: Put process  1 to run queue
	CPU 3: Dispatched process  2
	CPU 0: Dispatched process  1
liballoc:184
print_pgtbl:
 PGD=7f0fa4007770 P4D=7f0fa0000bd0 PUD=7f0fa0001be0 PMD=7f0fa0002bf0
Time slot   5
libwrite: PID 1 writing value 100 to offset 20
print_pgtbl:
 PGD=7f0fa4007770 P4D=7f0fa0000bd0 PUD=7f0fa0001be0 PMD=7f0fa0002bf0
Time slot   6
liballoc:184
print_pgtbl:
 PGD=7f0fa400a220 P4D=7f0f98000bd0 PUD=7f0f98001be0 PMD=7f0f98002bf0
	CPU 1: Put process  3 to run queue
	CPU 1: Dispatched process  3
	CPU 2: Put process  4 to run queue
	CPU 2: Dispatched process  4
	CPU 3: Put process  2 to run queue
	CPU 3: Dispatched process  2
libwrite: PID 2 writing value 102 to offset 20
print_pgtbl:
 PGD=7f0fa400a220 P4D=7f0f98000bd0 PUD=7f0f98001be0 PMD=7f0f98002bf0
	CPU 0: Put process  1 to run queue
	CPU 0: Dispatched process  1
libread:382
libread: PID 1 read value 100 from offset 20
print_pgtbl:
 PGD=7f0fa4007770 P4D=7f0fa0000bd0 PUD=7f0fa0001be0 PMD=7f0fa0002bf0
Time slot   7
libwrite: PID 1 writing value 102 to offset 20
print_pgtbl:
 PGD=7f0fa4007770 P4D=7f0fa0000bd0 PUD=7f0fa0001be0 PMD=7f0fa0002bf0
Time slot   8
libwrite: PID 2 writing value 1 to offset 1000
print_pgtbl:
 PGD=7f0fa400a220 P4D=7f0f98000bd0 PUD=7f0f98001be0 PMD=7f0f98002bf0
	Loaded a process at input/proc/m1s, PID: 5 PRIO: 15
	CPU 2: Put process  4 to run queue
	CPU 2: Dispatched process  5
	CPU 1: Put process  3 to run queue
	CPU 1: Dispatched process  4
	CPU 0: Put process  1 to run queue
liballoc:184
	CPU 0: Dispatched process  3
print_pgtbl:
 PGD=7f0fa4012450 P4D=7f0f98004c80 PUD=7f0f98005c90 PMD=7f0f98006ca0
Time slot   9
	CPU 3: Processed  2 has finished
	CPU 3: Dispatched process  1
libread:382
libread: PID 1 read value -85 from offset 20
print_pgtbl:
 PGD=7f0fa4007770 P4D=7f0fa0000bd0 PUD=7f0fa0001be0 PMD=7f0fa0002bf0
liballoc:184
print_pgtbl:
 PGD=7f0fa4012450 P4D=7f0f98004c80 PUD=7f0f98005c90 PMD=7f0f98006ca0
Time slot  10
	Loaded a process at input/proc/p1s, PID: 6 PRIO: 15
	CPU 1: Put process  4 to run queue
	CPU 1: Dispatched process  6
	CPU 0: Put process  3 to run queue
	CPU 0: Dispatched process  4
Time slot  11
	CPU 2: Put process  5 to run queue
	CPU 2: Dispatched process  5
	CPU 3: Put process  1 to run queue
	CPU 3: Dispatched process  3
Time slot  12
liballoc:184
print_pgtbl:
 PGD=7f0fa4012450 P4D=7f0f98004c80 PUD=7f0f98005c90 PMD=7f0f98006ca0
Time slot  13
	CPU 0: Put process  4 to run queue
	CPU 0: Dispatched process  4
	CPU 1: Put process  6 to run queue
	CPU 1: Dispatched process  6
	Loaded a process at input/proc/s2, PID: 7 PRIO: 120
	CPU 2: Put process  5 to run queue
	CPU 2: Dispatched process  5
	CPU 3: Put process  3 to run queue
	CPU 3: Dispatched process  3
Time slot  14
	CPU 1: Put process  6 to run queue
	CPU 1: Dispatched process  6
	CPU 0: Put process  4 to run queue
	CPU 0: Dispatched process  4
Time slot  15
	CPU 2: Processed  5 has finished
	CPU 2: Dispatched process  7
	CPU 3: Put process  3 to run queue
	CPU 3: Dispatched process  3
	Loaded a process at input/proc/s1, PID: 8 PRIO: 0
Time slot  16
	CPU 3: Processed  3 has finished
	CPU 3: Dispatched process  8
	CPU 1: Put process  6 to run queue
	CPU 1: Dispatched process  6
	CPU 0: Put process  4 to run queue
	CPU 0: Dispatched process  4
Time slot  17
	CPU 2: Put process  7 to run queue
	CPU 2: Dispatched process  7
Time slot  18
	CPU 3: Put process  8 to run queue
	CPU 3: Dispatched process  8
	CPU 1: Put process  6 to run queue
	CPU 1: Dispatched process  6
	CPU 0: Put process  4 to run queue
	CPU 0: Dispatched process  4
Time slot  19
	CPU 2: Put process  7 to run queue
	CPU 2: Dispatched process  7
	CPU 0: Processed  4 has finished
	CPU 0: Dispatched process  1
libread:382
libread: PID 1 read value -79 from offset 20
print_pgtbl:
 PGD=7f0fa4007770 P4D=7f0fa0000bd0 PUD=7f0fa0001be0 PMD=7f0fa0002bf0
Time slot  20
	CPU 3: Put process  8 to run queue
	CPU 3: Dispatched process  8
	CPU 1: Processed  6 has finished
	CPU 1 stopped
Time slot  21
	CPU 2: Put process  7 to run queue
	CPU 2: Dispatched process  7
	CPU 0: Put process  1 to run queue
	CPU 0: Dispatched process  1
Time slot  22
	CPU 3: Put process  8 to run queue
	CPU 3: Dispatched process  8
Time slot  23
	CPU 2: Put process  7 to run queue
	CPU 2: Dispatched process  7
	CPU 3: Processed  8 has finished
	CPU 3 stopped
	CPU 0: Processed  1 has finished
	CPU 0 stopped
Time slot  24
Time slot  25
	CPU 2: Put process  7 to run queue
	CPU 2: Dispatched process  7
Time slot  26
Time slot  27
	CPU 2: Processed  7 has finished
	CPU 2 stopped
