Time slot   0
ld_routine
Time slot   1
	Loaded a process at input/proc/p1s, PID: 1 PRIO: 15
	CPU 1: Dispatched process  1
Time slot   2
Time slot   3
	CPU 1: Put process  1 to run queue
	CPU 1: Dispatched process  1
Time slot   4
Time slot   5
	CPU 1: Put process  1 to run queue
	CPU 1: Dispatched process  1
	Loaded a process at input/proc/m0s, PID: 2 PRIO: 120
	CPU 2: Dispatched process  2
liballoc:185
print_pgtbl:
 PGD=7f278400a160 P4D=7f277c000bd0 PUD=7f277c001be0 PMD=7f277c002bf0
Time slot   6
liballoc:185
print_pgtbl:
 PGD=7f278400a160 P4D=7f277c000bd0 PUD=7f277c001be0 PMD=7f277c002bf0
	CPU 1: Put process  1 to run queue
	CPU 1: Dispatched process  1
Time slot   7
	Loaded a process at input/proc/p0s, PID: 3 PRIO: 130
	CPU 2: Put process  2 to run queue
	CPU 2: Dispatched process  2
Time slot   8
	CPU 0: Dispatched process  3
Time slot   9
liballoc:185
print_pgtbl:
 PGD=7f278400cd40 P4D=7f277c004c80 PUD=7f277c005c90 PMD=7f277c006ca0
	CPU 1: Put process  1 to run queue
	CPU 1: Dispatched process  1
liballoc:185
print_pgtbl:
 PGD=7f278400cd40 P4D=7f277c004c80 PUD=7f277c005c90 PMD=7f277c006ca0
	Loaded a process at input/proc/s0, PID: 4 PRIO: 38
	CPU 3: Dispatched process  4
Time slot  10
	CPU 0: Put process  3 to run queue
	CPU 0: Dispatched process  3
liballoc:185
print_pgtbl:
 PGD=7f278400f940 P4D=7f2780000c40 PUD=7f2780001c50 PMD=7f2780002c60
	CPU 2: Put process  2 to run queue
	CPU 2: Dispatched process  2
	CPU 1: Processed  1 has finished
	Loaded a process at input/proc/s3, PID: 5 PRIO: 39
Time slot  11
	CPU 1: Dispatched process  5
Time slot  12
	CPU 3: Put process  4 to run queue
	CPU 3: Dispatched process  4
	CPU 0: Put process  3 to run queue
	CPU 0: Dispatched process  3
liballoc:185
print_pgtbl:
 PGD=7f27840124a0 P4D=7f2780004cf0 PUD=7f2780005d00 PMD=7f2780006d10
	CPU 2: Processed  2 has finished
Time slot  13
print_pgtbl:
 PGD=7f27840124a0 P4D=7f2780004cf0 PUD=7f2780005d00 PMD=7f2780006d10
Time slot  14
	Loaded a process at input/proc/m1s, PID: 6 PRIO: 15
	CPU 3: Put process  4 to run queue
	CPU 3: Dispatched process  6
liballoc:185
print_pgtbl:
 PGD=7f2784014f40 P4D=7f2778000bd0 PUD=7f2778001be0 PMD=7f2778002bf0
	CPU 2: Dispatched process  4
	CPU 1: Put process  5 to run queue
	CPU 1: Dispatched process  5
	CPU 0: Put process  3 to run queue
	CPU 0: Dispatched process  3
libread:385
print_pgtbl:
 PGD=7f2784014f40 P4D=7f2778000bd0 PUD=7f2778001be0 PMD=7f2778002bf0
Time slot  15
liballoc:185
print_pgtbl:
 PGD=7f2784014f40 P4D=7f2778000bd0 PUD=7f2778001be0 PMD=7f2778002bf0
	Loaded a process at input/proc/s2, PID: 7 PRIO: 120
	CPU 3: Put process  6 to run queue
	CPU 3: Dispatched process  6
Time slot  16
	CPU 0: Put process  3 to run queue
	CPU 0: Dispatched process  7
	CPU 1: Put process  5 to run queue
	CPU 1: Dispatched process  5
	CPU 2: Put process  4 to run queue
	CPU 2: Dispatched process  4
liballoc:185
print_pgtbl:
 PGD=7f2784017ad0 P4D=7f2778004c80 PUD=7f2778005c90 PMD=7f2778006ca0
	Loaded a process at input/proc/s1, PID: 8 PRIO: 0
Time slot  17
	CPU 3: Put process  6 to run queue
	CPU 3: Dispatched process  8
	CPU 1: Put process  5 to run queue
	CPU 1: Dispatched process  6
	CPU 0: Put process  7 to run queue
	CPU 0: Dispatched process  5
Time slot  18
	CPU 2: Put process  4 to run queue
	CPU 2: Dispatched process  4
Time slot  19
	CPU 3: Put process  8 to run queue
	CPU 3: Dispatched process  8
Time slot  20
	CPU 1: Processed  6 has finished
	CPU 1: Dispatched process  7
	CPU 0: Put process  5 to run queue
	CPU 0: Dispatched process  5
	CPU 2: Put process  4 to run queue
	CPU 2: Dispatched process  4
Time slot  21
Time slot  22
	CPU 3: Put process  8 to run queue
	CPU 3: Dispatched process  8
	CPU 1: Put process  7 to run queue
	CPU 1: Dispatched process  7
	CPU 0: Put process  5 to run queue
	CPU 0: Dispatched process  5
	CPU 2: Put process  4 to run queue
	CPU 2: Dispatched process  4
Time slot  23
	CPU 0: Processed  5 has finished
	CPU 0: Dispatched process  3
libread:385
print_pgtbl:
 PGD=7f278401a590 P4D=0 PUD=0 PMD=0
	CPU 1: Put process  7 to run queue
	CPU 1: Dispatched process  7
Time slot  24
	CPU 2: Put process  4 to run queue
	CPU 2: Dispatched process  4
	CPU 3: Put process  8 to run queue
	CPU 3: Dispatched process  8
Time slot  25
	CPU 0: Put process  3 to run queue
	CPU 0: Dispatched process  3
libread:385
print_pgtbl:
 PGD=7f278401a590 P4D=0 PUD=0 PMD=0
	CPU 3: Processed  8 has finished
	CPU 3 stopped
	CPU 2: Processed  4 has finished
	CPU 2 stopped
Time slot  26
	CPU 1: Put process  7 to run queue
	CPU 1: Dispatched process  7
Time slot  27
	CPU 0: Put process  3 to run queue
	CPU 0: Dispatched process  3
Time slot  28
	CPU 1: Put process  7 to run queue
	CPU 1: Dispatched process  7
Time slot  29
	CPU 0: Processed  3 has finished
	CPU 0 stopped
Time slot  30
	CPU 1: Processed  7 has finished
	CPU 1 stopped
