Time slot   0
ld_routine
Time slot   1
	Loaded a process at input/proc/p0s, PID: 1 PRIO: 130
	CPU 1: Dispatched process  1
Time slot   2
liballoc:185
print_pgtbl:
 PGD=7f7dc4007760 P4D=7f7dc0000bd0 PUD=7f7dc0001be0 PMD=7f7dc0002bf0
Time slot   3
	CPU 1: Put process  1 to run queue
	CPU 1: Dispatched process  1
liballoc:185
print_pgtbl:
 PGD=7f7dc4007760 P4D=7f7dc0000bd0 PUD=7f7dc0001be0 PMD=7f7dc0002bf0
	Loaded a process at input/proc/m0s, PID: 2 PRIO: 120
	CPU 3: Dispatched process  2
liballoc:185
print_pgtbl:
 PGD=7f7dc400a200 P4D=7f7db8000bd0 PUD=7f7db8001be0 PMD=7f7db8002bf0
Time slot   4
libfree:210
print_pgtbl:
 PGD=7f7dc400a200 P4D=7f7db8000bd0 PUD=7f7db8001be0 PMD=7f7db8002bf0
	Loaded a process at input/proc/s1, PID: 3 PRIO: 0
liballoc:185
print_pgtbl:
 PGD=7f7dc400ccc0 P4D=7f7db8004c80 PUD=7f7db8005c90 PMD=7f7db8006ca0
Time slot   5
	CPU 2: Dispatched process  3
	CPU 1: Put process  1 to run queue
	CPU 1: Dispatched process  1
liballoc:185
print_pgtbl:
 PGD=7f7dc400ccc0 P4D=7f7db8004c80 PUD=7f7db8005c90 PMD=7f7db8006ca0
	CPU 3: Put process  2 to run queue
	CPU 3: Dispatched process  2
Time slot   6
	Loaded a process at input/proc/p1s, PID: 4 PRIO: 15
liballoc:185
print_pgtbl:
 PGD=7f7dc400f800 P4D=7f7db8008d10 PUD=7f7db8009d20 PMD=7f7db800ad30
	CPU 2: Put process  3 to run queue
	CPU 2: Dispatched process  3
	CPU 0: Dispatched process  4
Time slot   7
	CPU 1: Put process  1 to run queue
	CPU 1: Dispatched process  1
libread:385
print_pgtbl:
 PGD=7f7dc400f800 P4D=7f7db8008d10 PUD=7f7db8009d20 PMD=7f7db800ad30
	CPU 3: Put process  2 to run queue
	CPU 3: Dispatched process  2
Time slot   8
print_pgtbl:
 PGD=7f7dc400f800 P4D=7f7db8008d10 PUD=7f7db8009d20 PMD=7f7db800ad30
print_pgtbl:
 PGD=7f7dc400f800 P4D=7f7db8008d10 PUD=7f7db8009d20 PMD=7f7db800ad30
	CPU 2: Put process  3 to run queue
	CPU 2: Dispatched process  3
	Loaded a process at input/proc/s3, PID: 5 PRIO: 39
	CPU 1: Put process  1 to run queue
	CPU 1: Dispatched process  5
	CPU 0: Put process  4 to run queue
	CPU 0: Dispatched process  4
Time slot   9
	CPU 3: Processed  2 has finished
	CPU 3: Dispatched process  1
libread:385
print_pgtbl:
 PGD=7f7dc4012360 P4D=0 PUD=0 PMD=0
Time slot  10
	Loaded a process at input/proc/s2, PID: 6 PRIO: 120
	Loaded a process at input/proc/m1s, PID: 7 PRIO: 15
	CPU 2: Put process  3 to run queue
	CPU 2: Dispatched process  3
Time slot  11
	CPU 0: Put process  4 to run queue
	CPU 0: Dispatched process  7
liballoc:185
print_pgtbl:
 PGD=7f7dc4017990 P4D=0 PUD=0 PMD=0
	CPU 1: Put process  5 to run queue
	CPU 1: Dispatched process  4
	Loaded a process at input/proc/s0, PID: 8 PRIO: 38
Time slot  12
	CPU 2: Processed  3 has finished
	CPU 2: Dispatched process  8
	CPU 3: Put process  1 to run queue
	CPU 3: Dispatched process  5
liballoc:185
print_pgtbl:
 PGD=7f7dc401a590 P4D=0 PUD=0 PMD=0
Time slot  13
	CPU 0: Put process  7 to run queue
	CPU 0: Dispatched process  7
	CPU 1: Put process  4 to run queue
	CPU 1: Dispatched process  4
	CPU 2: Put process  8 to run queue
	CPU 2: Dispatched process  8
liballoc:185
print_pgtbl:
 PGD=7f7dc401a590 P4D=0 PUD=0 PMD=0
Time slot  14
	CPU 3: Put process  5 to run queue
	CPU 3: Dispatched process  5
Time slot  15
	CPU 1: Put process  4 to run queue
	CPU 1: Dispatched process  4
	CPU 0: Put process  7 to run queue
	CPU 0: Dispatched process  7
libfree:210
print_pgtbl:
 PGD=7f7dc401a590 P4D=0 PUD=0 PMD=0
	CPU 2: Put process  8 to run queue
	CPU 2: Dispatched process  8
	CPU 3: Put process  5 to run queue
	CPU 3: Dispatched process  5
Time slot  16
libfree:210
print_pgtbl:
 PGD=7f7dc401a590 P4D=0 PUD=0 PMD=0
Time slot  17
	CPU 1: Processed  4 has finished
	CPU 1: Dispatched process  6
	CPU 0: Processed  7 has finished
	CPU 0: Dispatched process  1
libread:385
print_pgtbl:
 PGD=7f7dc401a590 P4D=0 PUD=0 PMD=0
	CPU 2: Put process  8 to run queue
	CPU 2: Dispatched process  8
	CPU 3: Put process  5 to run queue
	CPU 3: Dispatched process  5
Time slot  18
Time slot  19
	CPU 1: Put process  6 to run queue
	CPU 1: Dispatched process  6
	CPU 0: Put process  1 to run queue
	CPU 0: Dispatched process  1
	CPU 2: Put process  8 to run queue
	CPU 2: Dispatched process  8
	CPU 3: Put process  5 to run queue
Time slot  20
	CPU 3: Dispatched process  5
Time slot  21
	CPU 1: Put process  6 to run queue
	CPU 1: Dispatched process  6
	CPU 3: Processed  5 has finished
	CPU 3 stopped
	CPU 0: Processed  1 has finished
	CPU 0 stopped
	CPU 2: Put process  8 to run queue
	CPU 2: Dispatched process  8
Time slot  22
Time slot  23
	CPU 1: Put process  6 to run queue
	CPU 1: Dispatched process  6
Time slot  24
	CPU 2: Put process  8 to run queue
	CPU 2: Dispatched process  8
Time slot  25
	CPU 1: Put process  6 to run queue
	CPU 1: Dispatched process  6
Time slot  26
	CPU 2: Put process  8 to run queue
	CPU 2: Dispatched process  8
Time slot  27
	CPU 2: Processed  8 has finished
	CPU 2 stopped
	CPU 1: Put process  6 to run queue
	CPU 1: Dispatched process  6
Time slot  28
Time slot  29
	CPU 1: Processed  6 has finished
	CPU 1 stopped
