Time slot   0
ld_routine
Time slot   1
	Loaded a process at input/proc/p0s, PID: 1 PRIO: 130
Time slot   2
	CPU 0: Dispatched process  1
	Loaded a process at input/proc/m0s, PID: 2 PRIO: 120
	CPU 3: Dispatched process  2
liballoc:185
print_pgtbl:
 PGD=7f0b4400a200 P4D=7f0b48000bd0 PUD=7f0b48001be0 PMD=7f0b48002bf0
Time slot   3
liballoc:185
print_pgtbl:
 PGD=7f0b4400a200 P4D=7f0b48000bd0 PUD=7f0b48001be0 PMD=7f0b48002bf0
Time slot   4
liballoc:185
print_pgtbl:
 PGD=7f0b4400a200 P4D=7f0b48000bd0 PUD=7f0b48001be0 PMD=7f0b48002bf0
	CPU 0: Put process  1 to run queue
	CPU 0: Dispatched process  1
liballoc:185
print_pgtbl:
 PGD=7f0b4400a200 P4D=7f0b48000bd0 PUD=7f0b48001be0 PMD=7f0b48002bf0
	Loaded a process at input/proc/s3, PID: 3 PRIO: 39
	Loaded a process at input/proc/s0, PID: 4 PRIO: 38
Time slot   5
	CPU 1: Dispatched process  4
	CPU 2: Dispatched process  3
	CPU 3: Put process  2 to run queue
	CPU 3: Dispatched process  2
liballoc:185
print_pgtbl:
 PGD=7f0b4400f960 P4D=7f0b48004c80 PUD=7f0b48005c90 PMD=7f0b48006ca0
Time slot   6
	CPU 0: Put process  1 to run queue
	CPU 0: Dispatched process  1
liballoc:185
print_pgtbl:
 PGD=7f0b4400f960 P4D=7f0b48004c80 PUD=7f0b48005c90 PMD=7f0b48006ca0
	CPU 3: Put process  2 to run queue
	CPU 3: Dispatched process  2
print_pgtbl:
 PGD=7f0b4400f960 P4D=7f0b48004c80 PUD=7f0b48005c90 PMD=7f0b48006ca0
	CPU 2: Put process  3 to run queue
	CPU 2: Dispatched process  3
	CPU 1: Put process  4 to run queue
	CPU 1: Dispatched process  4
Time slot   7
print_pgtbl:
 PGD=7f0b4400f960 P4D=7f0b48004c80 PUD=7f0b48005c90 PMD=7f0b48006ca0
print_pgtbl:
 PGD=7f0b4400f960 P4D=7f0b48004c80 PUD=7f0b48005c90 PMD=7f0b48006ca0
Time slot   8
	CPU 0: Put process  1 to run queue
	CPU 0: Dispatched process  1
libread:385
print_pgtbl:
 PGD=7f0b4400f960 P4D=7f0b48004c80 PUD=7f0b48005c90 PMD=7f0b48006ca0
	Loaded a process at input/proc/m1s, PID: 5 PRIO: 15
	CPU 3: Processed  2 has finished
	CPU 3: Dispatched process  5
liballoc:185
print_pgtbl:
 PGD=7f0b44012400 P4D=7f0b48008d10 PUD=7f0b48009d20 PMD=7f0b4800ad30
	CPU 2: Put process  3 to run queue
	CPU 2: Dispatched process  3
	CPU 1: Put process  4 to run queue
	CPU 1: Dispatched process  4
Time slot   9
liballoc:185
print_pgtbl:
 PGD=7f0b44012400 P4D=7f0b48008d10 PUD=7f0b48009d20 PMD=7f0b4800ad30
Time slot  10
	CPU 0: Put process  1 to run queue
	CPU 0: Dispatched process  1
libread:385
print_pgtbl:
 PGD=7f0b44012400 P4D=7f0b48008d10 PUD=7f0b48009d20 PMD=7f0b4800ad30
	Loaded a process at input/proc/p1s, PID: 6 PRIO: 15
	CPU 3: Put process  5 to run queue
	CPU 3: Dispatched process  6
	CPU 2: Put process  3 to run queue
	CPU 2: Dispatched process  5
	CPU 1: Put process  4 to run queue
	CPU 1: Dispatched process  4
Time slot  11
Time slot  12
liballoc:185
print_pgtbl:
 PGD=7f0b44014f40 P4D=7f0b40000bd0 PUD=7f0b40001be0 PMD=7f0b40002bf0
	CPU 0: Put process  1 to run queue
	CPU 0: Dispatched process  3
	CPU 3: Put process  6 to run queue
	CPU 3: Dispatched process  6
	CPU 1: Put process  4 to run queue
	CPU 1: Dispatched process  4
Time slot  13
	CPU 2: Put process  5 to run queue
	CPU 2: Dispatched process  5
libfree:210
print_pgtbl:
 PGD=7f0b44014f40 P4D=7f0b40000bd0 PUD=7f0b40001be0 PMD=7f0b40002bf0
	Loaded a process at input/proc/s2, PID: 7 PRIO: 120
Time slot  14
	CPU 0: Put process  3 to run queue
	CPU 0: Dispatched process  3
	CPU 3: Put process  6 to run queue
	CPU 3: Dispatched process  6
	CPU 2: Processed  5 has finished
	CPU 2: Dispatched process  7
	CPU 1: Put process  4 to run queue
	CPU 1: Dispatched process  4
Time slot  15
Time slot  16
	Loaded a process at input/proc/s1, PID: 8 PRIO: 0
	CPU 0: Put process  3 to run queue
	CPU 0: Dispatched process  8
Time slot  17
	CPU 1: Put process  4 to run queue
	CPU 1: Dispatched process  4
	CPU 2: Put process  7 to run queue
	CPU 2: Dispatched process  3
	CPU 3: Put process  6 to run queue
	CPU 3: Dispatched process  6
	CPU 2: Processed  3 has finished
	CPU 2: Dispatched process  7
Time slot  18
	CPU 0: Put process  8 to run queue
	CPU 0: Dispatched process  8
	CPU 1: Put process  4 to run queue
	CPU 1: Dispatched process  4
Time slot  19
	CPU 3: Put process  6 to run queue
	CPU 3: Dispatched process  6
	CPU 2: Put process  7 to run queue
	CPU 2: Dispatched process  7
	CPU 1: Processed  4 has finished
	CPU 1: Dispatched process  1
libread:385
print_pgtbl:
 PGD=7f0b4401a590 P4D=0 PUD=0 PMD=0
	CPU 0: Put process  8 to run queue
	CPU 0: Dispatched process  8
Time slot  20
	CPU 3: Processed  6 has finished
	CPU 3 stopped
Time slot  21
	CPU 2: Put process  7 to run queue
	CPU 2: Dispatched process  7
	CPU 1: Put process  1 to run queue
	CPU 1: Dispatched process  1
	CPU 0: Put process  8 to run queue
	CPU 0: Dispatched process  8
Time slot  22
	CPU 0: Processed  8 has finished
	CPU 0 stopped
Time slot  23
	CPU 2: Put process  7 to run queue
	CPU 2: Dispatched process  7
	CPU 1: Processed  1 has finished
	CPU 1 stopped
Time slot  24
Time slot  25
	CPU 2: Put process  7 to run queue
	CPU 2: Dispatched process  7
Time slot  26
Time slot  27
	CPU 2: Processed  7 has finished
	CPU 2 stopped
Time slot  28
