Time slot   0
ld_routine
	Loaded a process at input/proc/p1s, PID: 1 PRIO: 15
Time slot   1
	CPU 3: Dispatched process  1
Time slot   2
	CPU 3: Put process  1 to run queue
	CPU 3: Dispatched process  1
Time slot   3
Time slot   4
	Loaded a process at input/proc/m0s, PID: 2 PRIO: 120
	CPU 3: Put process  1 to run queue
	CPU 3: Dispatched process  1
	CPU 2: Dispatched process  2
liballoc:185
print_pgtbl:
 PGD=7f03f400a160 P4D=7f03ec000bd0 PUD=7f03ec001be0 PMD=7f03ec002bf0
Time slot   5
liballoc:185
print_pgtbl:
 PGD=7f03f400a160 P4D=7f03ec000bd0 PUD=7f03ec001be0 PMD=7f03ec002bf0
Time slot   6
	Loaded a process at input/proc/p0s, PID: 3 PRIO: 130
	CPU 3: Put process  1 to run queue
	CPU 3: Dispatched process  1
	CPU 2: Put process  2 to run queue
	CPU 2: Dispatched process  2
	CPU 1: Dispatched process  3
Time slot   7
liballoc:185
print_pgtbl:
 PGD=7f03f400cd40 P4D=7f03ec004c80 PUD=7f03ec005c90 PMD=7f03ec006ca0
liballoc:185
print_pgtbl:
 PGD=7f03f400cd40 P4D=7f03ec004c80 PUD=7f03ec005c90 PMD=7f03ec006ca0
Time slot   8
	Loaded a process at input/proc/s0, PID: 4 PRIO: 38
	CPU 3: Put process  1 to run queue
	CPU 3: Dispatched process  1
	CPU 2: Put process  2 to run queue
	CPU 2: Dispatched process  4
	CPU 1: Put process  3 to run queue
	CPU 1: Dispatched process  2
	CPU 0: Dispatched process  3
liballoc:185
print_pgtbl:
 PGD=7f03f400f940 P4D=7f03e4000bd0 PUD=7f03e4001be0 PMD=7f03e4002bf0
Time slot   9
Time slot  10
	Loaded a process at input/proc/s3, PID: 5 PRIO: 39
	CPU 3: Processed  1 has finished
	CPU 3: Dispatched process  5
	CPU 2: Put process  4 to run queue
	CPU 2: Dispatched process  4
	CPU 1: Processed  2 has finished
	CPU 0: Put process  3 to run queue
	CPU 0: Dispatched process  3
liballoc:185
print_pgtbl:
 PGD=7f03f40124a0 P4D=7f03e4004c80 PUD=7f03e4005c90 PMD=7f03e4006ca0
Time slot  11
print_pgtbl:
 PGD=7f03f40124a0 P4D=7f03e4004c80 PUD=7f03e4005c90 PMD=7f03e4006ca0
Time slot  12
	CPU 3: Put process  5 to run queue
	CPU 3: Dispatched process  5
	CPU 2: Put process  4 to run queue
	CPU 2: Dispatched process  4
	CPU 0: Put process  3 to run queue
	CPU 0: Dispatched process  3
libread:385
print_pgtbl:
 PGD=7f03f40124a0 P4D=7f03e4004c80 PUD=7f03e4005c90 PMD=7f03e4006ca0
Time slot  13
	Loaded a process at input/proc/m1s, PID: 6 PRIO: 15
	CPU 1: Dispatched process  6
liballoc:185
print_pgtbl:
 PGD=7f03f4014f40 P4D=7f03f0000c40 PUD=7f03f0001c50 PMD=7f03f0002c60
Time slot  14
	CPU 3: Put process  5 to run queue
	CPU 3: Dispatched process  5
liballoc:185
print_pgtbl:
 PGD=7f03f4014f40 P4D=7f03f0000c40 PUD=7f03f0001c50 PMD=7f03f0002c60
	CPU 2: Put process  4 to run queue
	CPU 2: Dispatched process  4
	CPU 0: Put process  3 to run queue
	CPU 0: Dispatched process  3
libread:385
print_pgtbl:
 PGD=7f03f4014f40 P4D=7f03f0000c40 PUD=7f03f0001c50 PMD=7f03f0002c60
Time slot  15
	Loaded a process at input/proc/s2, PID: 7 PRIO: 120
	CPU 1: Put process  6 to run queue
	CPU 1: Dispatched process  6
Time slot  16
	Loaded a process at input/proc/s1, PID: 8 PRIO: 0
	CPU 3: Put process  5 to run queue
	CPU 3: Dispatched process  8
Time slot  17
	CPU 2: Put process  4 to run queue
	CPU 2: Dispatched process  4
	CPU 0: Put process  3 to run queue
	CPU 0: Dispatched process  5
liballoc:185
print_pgtbl:
 PGD=7f03f401a590 P4D=7f03f0004cf0 PUD=7f03f0005d00 PMD=7f03f0006d10
Time slot  18
	CPU 1: Put process  6 to run queue
	CPU 1: Dispatched process  6
libfree:210
print_pgtbl:
 PGD=7f03f401a590 P4D=7f03f0004cf0 PUD=7f03f0005d00 PMD=7f03f0006d10
Time slot  19
	CPU 0: Put process  5 to run queue
	CPU 0: Dispatched process  5
	CPU 2: Put process  4 to run queue
	CPU 2: Dispatched process  4
	CPU 3: Put process  8 to run queue
	CPU 3: Dispatched process  8
Time slot  20
	CPU 1: Processed  6 has finished
	CPU 1: Dispatched process  7
	CPU 2: Put process  4 to run queue
	CPU 2: Dispatched process  4
	CPU 3: Put process  8 to run queue
	CPU 3: Dispatched process  8
Time slot  21
	CPU 0: Put process  5 to run queue
	CPU 0: Dispatched process  5
	CPU 1: Put process  7 to run queue
	CPU 1: Dispatched process  7
Time slot  22
	CPU 0: Processed  5 has finished
	CPU 0: Dispatched process  3
libread:385
print_pgtbl:
 PGD=7f03f401a590 P4D=7f03f0004cf0 PUD=7f03f0005d00 PMD=7f03f0006d10
	CPU 3: Put process  8 to run queue
	CPU 3: Dispatched process  8
	CPU 2: Put process  4 to run queue
	CPU 2: Dispatched process  4
Time slot  23
	CPU 3: Processed  8 has finished
	CPU 3 stopped
	CPU 2: Processed  4 has finished
	CPU 2 stopped
	CPU 1: Put process  7 to run queue
	CPU 1: Dispatched process  7
	CPU 0: Put process  3 to run queue
	CPU 0: Dispatched process  3
Time slot  24
Time slot  25
	CPU 1: Put process  7 to run queue
	CPU 1: Dispatched process  7
	CPU 0: Processed  3 has finished
	CPU 0 stopped
Time slot  26
Time slot  27
	CPU 1: Put process  7 to run queue
	CPU 1: Dispatched process  7
Time slot  28
Time slot  29
	CPU 1: Put process  7 to run queue
	CPU 1: Dispatched process  7
Time slot  30
Time slot  31
	CPU 1: Processed  7 has finished
	CPU 1 stopped
