Time slot   0
ld_routine
Time slot   1
	Loaded a process at input/proc/p1s, PID: 1 PRIO: 15
	CPU 3: Dispatched process  1
Time slot   2
	CPU 3: Put process  1 to run queue
	CPU 3: Dispatched process  1
Time slot   3
Time slot   4
	CPU 3: Put process  1 to run queue
	CPU 3: Dispatched process  1
Time slot   5
	Loaded a process at input/proc/m0s, PID: 2 PRIO: 120
	CPU 2: Dispatched process  2
liballoc:184
print_pgtbl:
 PGD=7fa37c00a180 P4D=7fa374000bd0 PUD=7fa374001be0 PMD=7fa374002bf0
Time slot   6
liballoc:184
print_pgtbl:
 PGD=7fa37c00a180 P4D=7fa374000bd0 PUD=7fa374001be0 PMD=7fa374002bf0
	CPU 3: Put process  1 to run queue
	CPU 3: Dispatched process  1
Time slot   7
	Loaded a process at input/proc/p0s, PID: 3 PRIO: 130
	CPU 2: Put process  2 to run queue
	CPU 2: Dispatched process  2
	CPU 0: Dispatched process  3
Time slot   8
liballoc:184
print_pgtbl:
 PGD=7fa37c00a180 P4D=7fa374000bd0 PUD=7fa374001be0 PMD=7fa374002bf0
	CPU 3: Put process  1 to run queue
	CPU 3: Dispatched process  1
	CPU 2: Put process  2 to run queue
	CPU 2: Dispatched process  2
liballoc:184
print_pgtbl:
 PGD=7fa37c00cd70 P4D=7fa378000bd0 PUD=7fa378001be0 PMD=7fa378002bf0
Time slot   9
	Loaded a process at input/proc/s0, PID: 4 PRIO: 38
Time slot  10
	CPU 1: Dispatched process  4
	CPU 0: Put process  3 to run queue
	CPU 0: Dispatched process  3
liballoc:184
print_pgtbl:
 PGD=7fa37c00cd70 P4D=7fa378000bd0 PUD=7fa378001be0 PMD=7fa378002bf0
	CPU 3: Processed  1 has finished
Time slot  11
	Loaded a process at input/proc/s3, PID: 5 PRIO: 39
	CPU 3: Dispatched process  5
	CPU 2: Processed  2 has finished
Time slot  12
	CPU 0: Put process  3 to run queue
	CPU 0: Dispatched process  3
liballoc:184
print_pgtbl:
 PGD=7fa37c00cd70 P4D=7fa378000bd0 PUD=7fa378001be0 PMD=7fa378002bf0
	CPU 1: Put process  4 to run queue
	CPU 1: Dispatched process  4
Time slot  13
libwrite: PID 3 writing value 100 to offset 20
print_pgtbl:
 PGD=7fa37c00cd70 P4D=7fa378000bd0 PUD=7fa378001be0 PMD=7fa378002bf0
	CPU 3: Put process  5 to run queue
	CPU 3: Dispatched process  5
	Loaded a process at input/proc/m1s, PID: 6 PRIO: 15
	CPU 2: Dispatched process  6
liballoc:184
print_pgtbl:
 PGD=7fa37c014fa0 P4D=7fa374004cd0 PUD=7fa374005ce0 PMD=7fa374006cf0
Time slot  14
	CPU 0: Put process  3 to run queue
	CPU 0: Dispatched process  3
libread:382
libread: PID 3 read value -125 from offset 20
print_pgtbl:
 PGD=7fa37c00cd70 P4D=7fa378000bd0 PUD=7fa378001be0 PMD=7fa378002bf0
	CPU 1: Put process  4 to run queue
	CPU 1: Dispatched process  4
	CPU 3: Put process  5 to run queue
Time slot  15
	CPU 3: Dispatched process  5
liballoc:184
print_pgtbl:
 PGD=7fa37c014fa0 P4D=7fa374004cd0 PUD=7fa374005ce0 PMD=7fa374006cf0
Time slot  16
	CPU 0: Put process  3 to run queue
	CPU 0: Dispatched process  3
libread:382
libread: PID 3 read value -125 from offset 20
print_pgtbl:
 PGD=7fa37c00cd70 P4D=7fa378000bd0 PUD=7fa378001be0 PMD=7fa378002bf0
	CPU 1: Put process  4 to run queue
	CPU 1: Dispatched process  4
	Loaded a process at input/proc/s2, PID: 7 PRIO: 120
	CPU 2: Put process  6 to run queue
	CPU 2: Dispatched process  6
	Loaded a process at input/proc/s1, PID: 8 PRIO: 0
Time slot  17
	CPU 3: Put process  5 to run queue
liballoc:184
print_pgtbl:
 PGD=7fa37c014fa0 P4D=7fa374004cd0 PUD=7fa374005ce0 PMD=7fa374006cf0
	CPU 3: Dispatched process  8
	CPU 0: Put process  3 to run queue
	CPU 0: Dispatched process  5
Time slot  18
	CPU 2: Put process  6 to run queue
	CPU 2: Dispatched process  6
libfree:209
print_pgtbl:
 PGD=7fa37c014fa0 P4D=7fa374004cd0 PUD=7fa374005ce0 PMD=7fa374006cf0
	CPU 1: Put process  4 to run queue
	CPU 1: Dispatched process  4
	CPU 3: Put process  8 to run queue
	CPU 3: Dispatched process  8
Time slot  19
	CPU 0: Put process  5 to run queue
	CPU 0: Dispatched process  5
Time slot  20
	CPU 1: Put process  4 to run queue
	CPU 1: Dispatched process  4
	CPU 2: Processed  6 has finished
	CPU 2: Dispatched process  7
	CPU 3: Put process  8 to run queue
	CPU 3: Dispatched process  8
Time slot  21
	CPU 0: Put process  5 to run queue
	CPU 0: Dispatched process  5
Time slot  22
	CPU 1: Put process  4 to run queue
	CPU 1: Dispatched process  4
	CPU 2: Put process  7 to run queue
	CPU 2: Dispatched process  7
	CPU 3: Put process  8 to run queue
	CPU 3: Dispatched process  8
	CPU 0: Processed  5 has finished
	CPU 0: Dispatched process  3
libread:382
libread: PID 3 read value -125 from offset 20
print_pgtbl:
 PGD=7fa37c00cd70 P4D=7fa378000bd0 PUD=7fa378001be0 PMD=7fa378002bf0
Time slot  23
	CPU 3: Processed  8 has finished
	CPU 3 stopped
Time slot  24
	CPU 1: Put process  4 to run queue
	CPU 1: Dispatched process  4
	CPU 2: Put process  7 to run queue
	CPU 2: Dispatched process  7
	CPU 0: Put process  3 to run queue
	CPU 0: Dispatched process  3
Time slot  25
	CPU 1: Processed  4 has finished
	CPU 1 stopped
Time slot  26
	CPU 2: Put process  7 to run queue
	CPU 2: Dispatched process  7
Time slot  27
	CPU 0: Processed  3 has finished
	CPU 0 stopped
Time slot  28
	CPU 2: Put process  7 to run queue
	CPU 2: Dispatched process  7
Time slot  29
Time slot  30
	CPU 2: Put process  7 to run queue
	CPU 2: Dispatched process  7
Time slot  31
Time slot  32
	CPU 2: Processed  7 has finished
	CPU 2 stopped
