Time slot   0
ld_routine
Time slot   1
	Loaded a process at input/proc/p0s, PID: 1 PRIO: 130
	CPU 3: Dispatched process  1
Time slot   2
	Loaded a process at input/proc/m0s, PID: 2 PRIO: 120
liballoc:185
print_pgtbl:
 PGD=7fc7b400a200 P4D=7fc7b8000bd0 PUD=7fc7b8001be0 PMD=7fc7b8002bf0
	CPU 2: Dispatched process  2
	CPU 3: Put process  1 to run queue
	CPU 3: Dispatched process  1
liballoc:185
print_pgtbl:
 PGD=7fc7b400a200 P4D=7fc7b8000bd0 PUD=7fc7b8001be0 PMD=7fc7b8002bf0
Time slot   3
liballoc:185
print_pgtbl:
 PGD=7fc7b400a200 P4D=7fc7b8000bd0 PUD=7fc7b8001be0 PMD=7fc7b8002bf0
liballoc:185
print_pgtbl:
 PGD=7fc7b400a200 P4D=7fc7b8000bd0 PUD=7fc7b8001be0 PMD=7fc7b8002bf0
Time slot   4
	Loaded a process at input/proc/s3, PID: 3 PRIO: 39
	CPU 2: Put process  2 to run queue
	CPU 2: Dispatched process  3
	CPU 1: Dispatched process  2
	Loaded a process at input/proc/s0, PID: 4 PRIO: 38
	CPU 0: Dispatched process  4
Time slot   5
	CPU 3: Put process  1 to run queue
	CPU 3: Dispatched process  1
liballoc:185
print_pgtbl:
 PGD=7fc7b400f960 P4D=7fc7b8004cf0 PUD=7fc7b8005d00 PMD=7fc7b8006d10
Time slot   6
liballoc:185
print_pgtbl:
 PGD=7fc7b400f960 P4D=7fc7b8004cf0 PUD=7fc7b8005d00 PMD=7fc7b8006d10
print_pgtbl:
 PGD=7fc7b400f960 P4D=7fc7b8004cf0 PUD=7fc7b8005d00 PMD=7fc7b8006d10
Time slot   7
	CPU 0: Put process  4 to run queue
	CPU 0: Dispatched process  4
	CPU 3: Put process  1 to run queue
	CPU 3: Dispatched process  1
libread:385
print_pgtbl:
 PGD=7fc7b400f960 P4D=7fc7b8004cf0 PUD=7fc7b8005d00 PMD=7fc7b8006d10
	CPU 2: Put process  3 to run queue
	CPU 2: Dispatched process  3
	CPU 1: Put process  2 to run queue
	CPU 1: Dispatched process  2
print_pgtbl:
 PGD=7fc7b400f960 P4D=7fc7b8004cf0 PUD=7fc7b8005d00 PMD=7fc7b8006d10
Time slot   8
print_pgtbl:
 PGD=7fc7b400f960 P4D=7fc7b8004cf0 PUD=7fc7b8005d00 PMD=7fc7b8006d10
print_pgtbl:
 PGD=7fc7b400f960 P4D=7fc7b8004cf0 PUD=7fc7b8005d00 PMD=7fc7b8006d10
Time slot   9
	CPU 2: Put process  3 to run queue
	CPU 2: Dispatched process  3
	CPU 1: Processed  2 has finished
	CPU 0: Put process  4 to run queue
	CPU 0: Dispatched process  4
	Loaded a process at input/proc/m1s, PID: 5 PRIO: 15
	CPU 3: Put process  1 to run queue
	CPU 3: Dispatched process  5
liballoc:185
print_pgtbl:
 PGD=7fc7b4012400 P4D=7fc7b8008d80 PUD=7fc7b8009d90 PMD=7fc7b800ada0
Time slot  10
liballoc:185
print_pgtbl:
 PGD=7fc7b4012400 P4D=7fc7b8008d80 PUD=7fc7b8009d90 PMD=7fc7b800ada0
	CPU 1: Dispatched process  1
libread:385
print_pgtbl:
 PGD=7fc7b4012400 P4D=7fc7b8008d80 PUD=7fc7b8009d90 PMD=7fc7b800ada0
Time slot  11
	CPU 3: Put process  5 to run queue
	CPU 3: Dispatched process  5
libfree:210
print_pgtbl:
 PGD=7fc7b4012400 P4D=7fc7b8008d80 PUD=7fc7b8009d90 PMD=7fc7b800ada0
	CPU 0: Put process  4 to run queue
	CPU 0: Dispatched process  4
	Loaded a process at input/proc/p1s, PID: 6 PRIO: 15
	CPU 2: Put process  3 to run queue
	CPU 2: Dispatched process  6
liballoc:185
print_pgtbl:
 PGD=7fc7b4014f40 P4D=7fc7b800ce60 PUD=7fc7b800de70 PMD=7fc7b800ee80
Time slot  12
	CPU 1: Put process  1 to run queue
	CPU 1: Dispatched process  3
	CPU 3: Put process  5 to run queue
	CPU 3: Dispatched process  5
libfree:210
print_pgtbl:
 PGD=7fc7b4014f40 P4D=7fc7b800ce60 PUD=7fc7b800de70 PMD=7fc7b800ee80
	CPU 0: Put process  4 to run queue
	CPU 0: Dispatched process  4
Time slot  13
	Loaded a process at input/proc/s2, PID: 7 PRIO: 120
	CPU 2: Put process  6 to run queue
	CPU 2: Dispatched process  6
Time slot  14
	CPU 1: Put process  3 to run queue
	CPU 1: Dispatched process  3
	CPU 3: Processed  5 has finished
	CPU 3: Dispatched process  7
	CPU 0: Put process  4 to run queue
	CPU 0: Dispatched process  4
Time slot  15
	CPU 2: Put process  6 to run queue
	CPU 2: Dispatched process  6
Time slot  16
	Loaded a process at input/proc/s1, PID: 8 PRIO: 0
	CPU 1: Put process  3 to run queue
	CPU 1: Dispatched process  8
Time slot  17
	CPU 2: Put process  6 to run queue
	CPU 2: Dispatched process  6
	CPU 0: Put process  4 to run queue
	CPU 0: Dispatched process  4
	CPU 3: Put process  7 to run queue
	CPU 3: Dispatched process  3
Time slot  18
	CPU 3: Processed  3 has finished
	CPU 3: Dispatched process  7
	CPU 1: Put process  8 to run queue
	CPU 1: Dispatched process  8
Time slot  19
	CPU 0: Put process  4 to run queue
	CPU 0: Dispatched process  4
	CPU 2: Put process  6 to run queue
	CPU 2: Dispatched process  6
Time slot  20
	CPU 1: Put process  8 to run queue
	CPU 1: Dispatched process  8
	CPU 0: Processed  4 has finished
	CPU 0: Dispatched process  1
libread:385
print_pgtbl:
 PGD=7fc7b401a590 P4D=0 PUD=0 PMD=0
	CPU 3: Put process  7 to run queue
	CPU 3: Dispatched process  7
Time slot  21
	CPU 2: Processed  6 has finished
	CPU 2 stopped
Time slot  22
	CPU 1: Put process  8 to run queue
	CPU 1: Dispatched process  8
	CPU 3: Put process  7 to run queue
	CPU 3: Dispatched process  7
	CPU 0: Put process  1 to run queue
	CPU 0: Dispatched process  1
	CPU 1: Processed  8 has finished
	CPU 1 stopped
Time slot  23
Time slot  24
	CPU 3: Put process  7 to run queue
	CPU 3: Dispatched process  7
	CPU 0: Processed  1 has finished
	CPU 0 stopped
Time slot  25
Time slot  26
	CPU 3: Put process  7 to run queue
	CPU 3: Dispatched process  7
Time slot  27
Time slot  28
	CPU 3: Processed  7 has finished
	CPU 3 stopped
