Time slot   0
ld_routine
Time slot   1
	Loaded a process at input/proc/p1s, PID: 1 PRIO: 15
	CPU 3: Dispatched process  1
Time slot   2
Time slot   3
	CPU 3: Put process  1 to run queue
	CPU 3: Dispatched process  1
Time slot   4
Time slot   5
	CPU 3: Put process  1 to run queue
	CPU 3: Dispatched process  1
	Loaded a process at input/proc/m0s, PID: 2 PRIO: 120
	CPU 1: Dispatched process  2
liballoc:185
print_pgtbl:
 PGD=7fc28800a160 P4D=7fc284000bd0 PUD=7fc284001be0 PMD=7fc284002bf0
Time slot   6
liballoc:185
print_pgtbl:
 PGD=7fc28800a160 P4D=7fc284000bd0 PUD=7fc284001be0 PMD=7fc284002bf0
Time slot   7
	CPU 3: Put process  1 to run queue
	CPU 3: Dispatched process  1
	Loaded a process at input/proc/p0s, PID: 3 PRIO: 130
	CPU 2: Dispatched process  3
	CPU 1: Put process  2 to run queue
	CPU 1: Dispatched process  2
Time slot   8
liballoc:185
print_pgtbl:
 PGD=7fc28800cd40 P4D=7fc27c000bd0 PUD=7fc27c001be0 PMD=7fc27c002bf0
liballoc:185
print_pgtbl:
 PGD=7fc28800cd40 P4D=7fc27c000bd0 PUD=7fc27c001be0 PMD=7fc27c002bf0
Time slot   9
	CPU 3: Put process  1 to run queue
	CPU 3: Dispatched process  1
	Loaded a process at input/proc/s0, PID: 4 PRIO: 38
	CPU 2: Put process  3 to run queue
	CPU 2: Dispatched process  4
	CPU 1: Put process  2 to run queue
	CPU 1: Dispatched process  2
	CPU 0: Dispatched process  3
liballoc:185
print_pgtbl:
 PGD=7fc28800f940 P4D=7fc280000bd0 PUD=7fc280001be0 PMD=7fc280002bf0
Time slot  10
Time slot  11
	Loaded a process at input/proc/s3, PID: 5 PRIO: 39
	CPU 3: Processed  1 has finished
	CPU 3: Dispatched process  5
	CPU 2: Put process  4 to run queue
	CPU 2: Dispatched process  4
	CPU 1: Processed  2 has finished
	CPU 0: Put process  3 to run queue
	CPU 0: Dispatched process  3
liballoc:185
print_pgtbl:
 PGD=7fc2880124a0 P4D=7fc280004c80 PUD=7fc280005c90 PMD=7fc280006ca0
Time slot  12
print_pgtbl:
 PGD=7fc2880124a0 P4D=7fc280004c80 PUD=7fc280005c90 PMD=7fc280006ca0
Time slot  13
	CPU 2: Put process  4 to run queue
	CPU 2: Dispatched process  4
	CPU 3: Put process  5 to run queue
	CPU 3: Dispatched process  5
	CPU 0: Put process  3 to run queue
	CPU 0: Dispatched process  3
libread:385
print_pgtbl:
 PGD=7fc2880124a0 P4D=7fc280004c80 PUD=7fc280005c90 PMD=7fc280006ca0
Time slot  14
	Loaded a process at input/proc/m1s, PID: 6 PRIO: 15
	CPU 1: Dispatched process  6
liballoc:185
print_pgtbl:
 PGD=7fc288014f40 P4D=7fc284004c80 PUD=7fc284005c90 PMD=7fc284006ca0
Time slot  15
	CPU 3: Put process  5 to run queue
	CPU 3: Dispatched process  5
	CPU 2: Put process  4 to run queue
	CPU 2: Dispatched process  4
liballoc:185
print_pgtbl:
 PGD=7fc288014f40 P4D=7fc284004c80 PUD=7fc284005c90 PMD=7fc284006ca0
	CPU 0: Put process  3 to run queue
	CPU 0: Dispatched process  3
libread:385
print_pgtbl:
 PGD=7fc288014f40 P4D=7fc284004c80 PUD=7fc284005c90 PMD=7fc284006ca0
Time slot  16
	Loaded a process at input/proc/s2, PID: 7 PRIO: 120
Time slot  17
	CPU 1: Put process  6 to run queue
	CPU 1: Dispatched process  6
	CPU 3: Put process  5 to run queue
	CPU 3: Dispatched process  5
	CPU 2: Put process  4 to run queue
	CPU 2: Dispatched process  4
	Loaded a process at input/proc/s1, PID: 8 PRIO: 0
Time slot  18
liballoc:185
print_pgtbl:
 PGD=7fc28801a590 P4D=7fc284008d30 PUD=7fc284009d40 PMD=7fc28400ad50
	CPU 0: Put process  3 to run queue
	CPU 0: Dispatched process  8
	CPU 3: Put process  5 to run queue
	CPU 3: Dispatched process  5
	CPU 1: Put process  6 to run queue
	CPU 1: Dispatched process  6
libfree:210
print_pgtbl:
 PGD=7fc28801a590 P4D=7fc284008d30 PUD=7fc284009d40 PMD=7fc28400ad50
Time slot  19
	CPU 2: Put process  4 to run queue
	CPU 2: Dispatched process  4
	CPU 0: Put process  8 to run queue
	CPU 0: Dispatched process  8
Time slot  20
	CPU 3: Put process  5 to run queue
	CPU 3: Dispatched process  5
	CPU 1: Processed  6 has finished
	CPU 1: Dispatched process  7
Time slot  21
	CPU 2: Put process  4 to run queue
	CPU 2: Dispatched process  4
	CPU 0: Put process  8 to run queue
	CPU 0: Dispatched process  8
Time slot  22
	CPU 3: Processed  5 has finished
	CPU 3: Dispatched process  3
libread:385
print_pgtbl:
 PGD=7fc28801a590 P4D=7fc284008d30 PUD=7fc284009d40 PMD=7fc28400ad50
	CPU 2: Put process  4 to run queue
	CPU 2: Dispatched process  4
	CPU 1: Put process  7 to run queue
	CPU 1: Dispatched process  7
Time slot  23
	CPU 0: Put process  8 to run queue
	CPU 0: Dispatched process  8
	CPU 3: Put process  3 to run queue
Time slot  24
	CPU 3: Dispatched process  3
	CPU 2: Processed  4 has finished
	CPU 2 stopped
	CPU 1: Put process  7 to run queue
	CPU 1: Dispatched process  7
	CPU 0: Processed  8 has finished
	CPU 0 stopped
Time slot  25
Time slot  26
	CPU 3: Processed  3 has finished
	CPU 3 stopped
Time slot  27
	CPU 1: Put process  7 to run queue
	CPU 1: Dispatched process  7
Time slot  28
Time slot  29
	CPU 1: Put process  7 to run queue
	CPU 1: Dispatched process  7
Time slot  30
Time slot  31
	CPU 1: Put process  7 to run queue
	CPU 1: Dispatched process  7
Time slot  32
Time slot  33
	CPU 1: Processed  7 has finished
	CPU 1 stopped
