Time slot   0
ld_routine
	Loaded a process at input/proc/p0s, PID: 1 PRIO: 130
	CPU 2: Dispatched process  1
Time slot   1
liballoc:185
print_pgtbl:
 PGD=7f4080007760 P4D=7f4084000bd0 PUD=7f4084001be0 PMD=7f4084002bf0
Time slot   2
	Loaded a process at input/proc/m0s, PID: 2 PRIO: 120
	CPU 3: Dispatched process  2
liballoc:185
print_pgtbl:
 PGD=7f408000a200 P4D=7f4078000bd0 PUD=7f4078001be0 PMD=7f4078002bf0
	CPU 2: Put process  1 to run queue
	CPU 2: Dispatched process  1
liballoc:185
print_pgtbl:
 PGD=7f408000a200 P4D=7f4078000bd0 PUD=7f4078001be0 PMD=7f4078002bf0
Time slot   3
	Loaded a process at input/proc/s3, PID: 3 PRIO: 39
Time slot   4
liballoc:185
print_pgtbl:
 PGD=7f408000cd60 P4D=7f4078004c80 PUD=7f4078005c90 PMD=7f4078006ca0
	CPU 1: Dispatched process  3
	Loaded a process at input/proc/s0, PID: 4 PRIO: 38
Time slot   5
	CPU 3: Put process  2 to run queue
	CPU 3: Dispatched process  4
	CPU 0: Dispatched process  2
	CPU 2: Put process  1 to run queue
	CPU 2: Dispatched process  1
liballoc:185
print_pgtbl:
 PGD=7f408000f960 P4D=7f4084004cf0 PUD=7f4084005d00 PMD=7f4084006d10
Time slot   6
	CPU 1: Put process  3 to run queue
	CPU 1: Dispatched process  3
liballoc:185
print_pgtbl:
 PGD=7f408000f960 P4D=7f4084004cf0 PUD=7f4084005d00 PMD=7f4084006d10
print_pgtbl:
 PGD=7f408000f960 P4D=7f4084004cf0 PUD=7f4084005d00 PMD=7f4084006d10
Time slot   7
	CPU 0: Put process  2 to run queue
	CPU 0: Dispatched process  2
print_pgtbl:
 PGD=7f408000f960 P4D=7f4084004cf0 PUD=7f4084005d00 PMD=7f4084006d10
	CPU 2: Put process  1 to run queue
	CPU 2: Dispatched process  1
libread:385
print_pgtbl:
 PGD=7f408000f960 P4D=7f4084004cf0 PUD=7f4084005d00 PMD=7f4084006d10
	CPU 3: Put process  4 to run queue
	CPU 3: Dispatched process  4
Time slot   8
print_pgtbl:
 PGD=7f408000f960 P4D=7f4084004cf0 PUD=7f4084005d00 PMD=7f4084006d10
	CPU 1: Put process  3 to run queue
	CPU 1: Dispatched process  3
print_pgtbl:
 PGD=7f408000f960 P4D=7f4084004cf0 PUD=7f4084005d00 PMD=7f4084006d10
	Loaded a process at input/proc/m1s, PID: 5 PRIO: 15
Time slot   9
	CPU 0: Processed  2 has finished
	CPU 0: Dispatched process  5
liballoc:185
print_pgtbl:
 PGD=7f4080012400 P4D=7f407c000bd0 PUD=7f407c001be0 PMD=7f407c002bf0
	CPU 2: Put process  1 to run queue
	CPU 2: Dispatched process  1
libread:385
print_pgtbl:
 PGD=7f4080012400 P4D=7f407c000bd0 PUD=7f407c001be0 PMD=7f407c002bf0
	CPU 3: Put process  4 to run queue
	CPU 3: Dispatched process  4
Time slot  10
liballoc:185
print_pgtbl:
 PGD=7f4080012400 P4D=7f407c000bd0 PUD=7f407c001be0 PMD=7f407c002bf0
	CPU 1: Put process  3 to run queue
	CPU 1: Dispatched process  3
	Loaded a process at input/proc/p1s, PID: 6 PRIO: 15
Time slot  11
	CPU 0: Put process  5 to run queue
	CPU 0: Dispatched process  6
	CPU 2: Put process  1 to run queue
	CPU 2: Dispatched process  5
	CPU 3: Put process  4 to run queue
	CPU 3: Dispatched process  4
Time slot  12
	CPU 1: Put process  3 to run queue
	CPU 1: Dispatched process  3
liballoc:185
print_pgtbl:
 PGD=7f4080014f40 P4D=7f4084008d80 PUD=7f4084009d90 PMD=7f408400ada0
	Loaded a process at input/proc/s2, PID: 7 PRIO: 120
Time slot  13
	CPU 0: Put process  6 to run queue
	CPU 0: Dispatched process  6
	CPU 2: Put process  5 to run queue
	CPU 2: Dispatched process  5
	CPU 3: Put process  4 to run queue
	CPU 3: Dispatched process  4
Time slot  14
	CPU 1: Put process  3 to run queue
	CPU 1: Dispatched process  3
Time slot  15
	CPU 0: Put process  6 to run queue
	CPU 0: Dispatched process  6
	CPU 2: Processed  5 has finished
	CPU 2: Dispatched process  7
	CPU 1: Processed  3 has finished
	CPU 1: Dispatched process  1
libread:385
print_pgtbl:
 PGD=7f4080017ad0 P4D=0 PUD=0 PMD=0
	CPU 3: Put process  4 to run queue
	CPU 3: Dispatched process  4
	Loaded a process at input/proc/s1, PID: 8 PRIO: 0
Time slot  16
Time slot  17
	CPU 0: Put process  6 to run queue
	CPU 0: Dispatched process  8
	CPU 1: Put process  1 to run queue
	CPU 1: Dispatched process  6
	CPU 2: Put process  7 to run queue
	CPU 2: Dispatched process  7
	CPU 3: Put process  4 to run queue
	CPU 3: Dispatched process  4
Time slot  18
Time slot  19
	CPU 0: Put process  8 to run queue
	CPU 1: Put process  6 to run queue
	CPU 1: Dispatched process  6
	CPU 2: Put process  7 to run queue
	CPU 2: Dispatched process  7
	CPU 3: Put process  4 to run queue
	CPU 3: Dispatched process  4
	CPU 0: Dispatched process  8
Time slot  20
	CPU 3: Processed  4 has finished
	CPU 3: Dispatched process  1
Time slot  21
	CPU 0: Put process  8 to run queue
	CPU 0: Dispatched process  8
	CPU 1: Processed  6 has finished
	CPU 1 stopped
	CPU 2: Put process  7 to run queue
	CPU 2: Dispatched process  7
Time slot  22
	CPU 3: Processed  1 has finished
	CPU 3 stopped
Time slot  23
	CPU 2: Put process  7 to run queue
	CPU 2: Dispatched process  7
	CPU 0: Put process  8 to run queue
	CPU 0: Dispatched process  8
Time slot  24
	CPU 0: Processed  8 has finished
	CPU 0 stopped
Time slot  25
	CPU 2: Put process  7 to run queue
	CPU 2: Dispatched process  7
Time slot  26
	CPU 2: Processed  7 has finished
	CPU 2 stopped
