Time slot   0
ld_routine
Time slot   1
	Loaded a process at input/proc/p0s, PID: 1 PRIO: 130
	CPU 3: Dispatched process  1
Time slot   2
liballoc:185
print_pgtbl:
 PGD=7f6090007760 P4D=7f6094000bd0 PUD=7f6094001be0 PMD=7f6094002bf0
Time slot   3
	CPU 3: Put process  1 to run queue
	CPU 3: Dispatched process  1
liballoc:185
print_pgtbl:
 PGD=7f6090007760 P4D=7f6094000bd0 PUD=7f6094001be0 PMD=7f6094002bf0
	Loaded a process at input/proc/m0s, PID: 2 PRIO: 120
	CPU 2: Dispatched process  2
liballoc:185
print_pgtbl:
 PGD=7f609000a200 P4D=7f6088000bd0 PUD=7f6088001be0 PMD=7f6088002bf0
libfree:210
print_pgtbl:
 PGD=7f609000a200 P4D=7f6088000bd0 PUD=7f6088001be0 PMD=7f6088002bf0
Time slot   4
liballoc:185
print_pgtbl:
 PGD=7f609000a200 P4D=7f6088000bd0 PUD=7f6088001be0 PMD=7f6088002bf0
Time slot   5
	Loaded a process at input/proc/s1, PID: 3 PRIO: 0
	CPU 3: Put process  1 to run queue
	CPU 3: Dispatched process  3
	CPU 2: Put process  2 to run queue
	CPU 2: Dispatched process  2
	CPU 1: Dispatched process  1
liballoc:185
print_pgtbl:
 PGD=7f609000ccc0 P4D=7f608c000bd0 PUD=7f608c001be0 PMD=7f608c002bf0
Time slot   6
	Loaded a process at input/proc/p1s, PID: 4 PRIO: 15
Time slot   7
	CPU 0: Dispatched process  4
liballoc:185
print_pgtbl:
 PGD=7f609000f800 P4D=7f6088004c80 PUD=7f6088005c90 PMD=7f6088006ca0
	CPU 3: Put process  3 to run queue
	CPU 3: Dispatched process  3
Time slot   8
	CPU 1: Put process  1 to run queue
	CPU 1: Dispatched process  1
libread:385
print_pgtbl:
 PGD=7f609000f800 P4D=7f6088004c80 PUD=7f6088005c90 PMD=7f6088006ca0
	CPU 2: Put process  2 to run queue
	CPU 2: Dispatched process  2
	Loaded a process at input/proc/s3, PID: 5 PRIO: 39
	CPU 3: Put process  3 to run queue
	CPU 3: Dispatched process  3
Time slot   9
	CPU 0: Put process  4 to run queue
	CPU 0: Dispatched process  4
	Loaded a process at input/proc/s2, PID: 6 PRIO: 120
Time slot  10
	CPU 1: Put process  1 to run queue
	CPU 1: Dispatched process  5
	CPU 2: Processed  2 has finished
	CPU 2: Dispatched process  6
Time slot  11
	Loaded a process at input/proc/m1s, PID: 7 PRIO: 15
	CPU 3: Put process  3 to run queue
	CPU 3: Dispatched process  3
	CPU 0: Put process  4 to run queue
	CPU 0: Dispatched process  7
liballoc:185
print_pgtbl:
 PGD=7f6090017990 P4D=0 PUD=0 PMD=0
	Loaded a process at input/proc/s0, PID: 8 PRIO: 38
	CPU 3: Processed  3 has finished
	CPU 3: Dispatched process  4
	CPU 1: Put process  5 to run queue
	CPU 1: Dispatched process  8
	CPU 2: Put process  6 to run queue
	CPU 2: Dispatched process  5
Time slot  12
liballoc:185
print_pgtbl:
 PGD=7f609001a590 P4D=0 PUD=0 PMD=0
	CPU 0: Put process  7 to run queue
	CPU 0: Dispatched process  7
Time slot  13
	CPU 2: Put process  5 to run queue
	CPU 2: Dispatched process  5
liballoc:185
print_pgtbl:
 PGD=7f609001a590 P4D=0 PUD=0 PMD=0
Time slot  14
	CPU 1: Put process  8 to run queue
	CPU 1: Dispatched process  8
	CPU 3: Put process  4 to run queue
	CPU 3: Dispatched process  4
	CPU 0: Put process  7 to run queue
	CPU 0: Dispatched process  7
libfree:210
print_pgtbl:
 PGD=7f609001a590 P4D=0 PUD=0 PMD=0
Time slot  15
	CPU 2: Put process  5 to run queue
	CPU 2: Dispatched process  5
libfree:210
print_pgtbl:
 PGD=7f609001a590 P4D=0 PUD=0 PMD=0
Time slot  16
	CPU 1: Put process  8 to run queue
	CPU 1: Dispatched process  8
	CPU 3: Put process  4 to run queue
	CPU 3: Dispatched process  4
	CPU 0: Processed  7 has finished
	CPU 0: Dispatched process  6
Time slot  17
	CPU 2: Put process  5 to run queue
	CPU 2: Dispatched process  5
Time slot  18
	CPU 1: Put process  8 to run queue
	CPU 1: Dispatched process  8
	CPU 3: Processed  4 has finished
	CPU 3: Dispatched process  1
libread:385
print_pgtbl:
 PGD=7f609001a590 P4D=0 PUD=0 PMD=0
	CPU 0: Put process  6 to run queue
	CPU 0: Dispatched process  6
Time slot  19
	CPU 3: Put process  1 to run queue
	CPU 3: Dispatched process  1
libread:385
print_pgtbl:
 PGD=7f609001a590 P4D=0 PUD=0 PMD=0
	CPU 2: Put process  5 to run queue
	CPU 2: Dispatched process  5
Time slot  20
	CPU 1: Put process  8 to run queue
	CPU 1: Dispatched process  8
	CPU 2: Processed  5 has finished
	CPU 2 stopped
Time slot  21
	CPU 0: Put process  6 to run queue
	CPU 0: Dispatched process  6
Time slot  22
	CPU 3: Put process  1 to run queue
	CPU 3: Dispatched process  1
	CPU 1: Put process  8 to run queue
	CPU 1: Dispatched process  8
	CPU 0: Put process  6 to run queue
	CPU 0: Dispatched process  6
Time slot  23
	CPU 3: Processed  1 has finished
	CPU 3 stopped
Time slot  24
	CPU 1: Put process  8 to run queue
	CPU 1: Dispatched process  8
	CPU 0: Put process  6 to run queue
	CPU 0: Dispatched process  6
Time slot  25
Time slot  26
	CPU 1: Put process  8 to run queue
	CPU 1: Dispatched process  8
	CPU 0: Processed  6 has finished
	CPU 0 stopped
Time slot  27
	CPU 1: Processed  8 has finished
	CPU 1 stopped
