Time slot   0
ld_routine
Time slot   1
	Loaded a process at input/proc/s3, PID: 1 PRIO: 3
	CPU 0: Dispatched process  1
Time slot   2
Time slot   3
	Loaded a process at input/proc/m0s, PID: 2 PRIO: 3
	CPU 0: Put process  1 to run queue
	CPU 0: Dispatched process  2
liballoc:184
print_pgtbl:
 PGD=7f6d2000a1a0 P4D=7f6d18000bd0 PUD=7f6d18001be0 PMD=7f6d18002bf0
	Loaded a process at input/proc/s4, PID: 3 PRIO: 4
Time slot   4
liballoc:184
print_pgtbl:
 PGD=7f6d2000a1a0 P4D=7f6d18000bd0 PUD=7f6d18001be0 PMD=7f6d18002bf0
Time slot   5
	Loaded a process at input/proc/s2, PID: 4 PRIO: 3
	CPU 0: Put process  2 to run queue
	CPU 0: Dispatched process  1
Time slot   6
Time slot   7
	Loaded a process at input/proc/p1s, PID: 5 PRIO: 2
	CPU 0: Put process  1 to run queue
	CPU 0: Dispatched process  5
Time slot   8
Time slot   9
	Loaded a process at input/proc/s0, PID: 6 PRIO: 1
	CPU 0: Put process  5 to run queue
	CPU 0: Dispatched process  6
Time slot  10
Time slot  11
	Loaded a process at input/proc/m1s, PID: 7 PRIO: 2
	CPU 0: Put process  6 to run queue
	CPU 0: Dispatched process  6
Time slot  12
Time slot  13
	CPU 0: Put process  6 to run queue
	CPU 0: Dispatched process  6
Time slot  14
Time slot  15
	Loaded a process at input/proc/s1, PID: 8 PRIO: 0
	CPU 0: Put process  6 to run queue
	CPU 0: Dispatched process  8
Time slot  16
Time slot  17
Time slot  18
	CPU 0: Put process  8 to run queue
	CPU 0: Dispatched process  8
Time slot  19
Time slot  20
	CPU 0: Put process  8 to run queue
	CPU 0: Dispatched process  8
Time slot  21
Time slot  22
	CPU 0: Put process  8 to run queue
	CPU 0: Dispatched process  8
Time slot  23
	CPU 0: Processed  8 has finished
	CPU 0: Dispatched process  6
Time slot  24
Time slot  25
	CPU 0: Put process  6 to run queue
	CPU 0: Dispatched process  6
Time slot  26
Time slot  27
	CPU 0: Put process  6 to run queue
	CPU 0: Dispatched process  6
Time slot  28
Time slot  29
	CPU 0: Put process  6 to run queue
	CPU 0: Dispatched process  6
Time slot  30
Time slot  31
	CPU 0: Put process  6 to run queue
	CPU 0: Dispatched process  6
Time slot  32
	CPU 0: Processed  6 has finished
	CPU 0: Dispatched process  5
Time slot  33
Time slot  34
	CPU 0: Put process  5 to run queue
	CPU 0: Dispatched process  7
liballoc:184
print_pgtbl:
 PGD=7f6d20017a20 P4D=7f6d18004cd0 PUD=7f6d18005ce0 PMD=7f6d18006cf0
Time slot  35
liballoc:184
print_pgtbl:
 PGD=7f6d20017a20 P4D=7f6d18004cd0 PUD=7f6d18005ce0 PMD=7f6d18006cf0
Time slot  36
	CPU 0: Put process  7 to run queue
	CPU 0: Dispatched process  5
Time slot  37
Time slot  38
	CPU 0: Put process  5 to run queue
	CPU 0: Dispatched process  7
libfree:209
print_pgtbl:
 PGD=7f6d20017a20 P4D=7f6d18004cd0 PUD=7f6d18005ce0 PMD=7f6d18006cf0
Time slot  39
liballoc:184
print_pgtbl:
 PGD=7f6d20017a20 P4D=7f6d18004cd0 PUD=7f6d18005ce0 PMD=7f6d18006cf0
Time slot  40
	CPU 0: Put process  7 to run queue
	CPU 0: Dispatched process  5
Time slot  41
Time slot  42
	CPU 0: Put process  5 to run queue
	CPU 0: Dispatched process  7
libfree:209
print_pgtbl:
 PGD=7f6d20017a20 P4D=7f6d18004cd0 PUD=7f6d18005ce0 PMD=7f6d18006cf0
Time slot  43
libfree:209
print_pgtbl:
 PGD=7f6d20017a20 P4D=7f6d18004cd0 PUD=7f6d18005ce0 PMD=7f6d18006cf0
Time slot  44
	CPU 0: Processed  7 has finished
	CPU 0: Dispatched process  5
Time slot  45
Time slot  46
	CPU 0: Processed  5 has finished
	CPU 0: Dispatched process  4
Time slot  47
Time slot  48
	CPU 0: Put process  4 to run queue
	CPU 0: Dispatched process  2
Time slot  49
liballoc:184
print_pgtbl:
 PGD=7f6d2000a1a0 P4D=7f6d18000bd0 PUD=7f6d18001be0 PMD=7f6d18002bf0
Time slot  50
	CPU 0: Put process  2 to run queue
	CPU 0: Dispatched process  1
Time slot  51
Time slot  52
	CPU 0: Put process  1 to run queue
	CPU 0: Dispatched process  4
Time slot  53
Time slot  54
	CPU 0: Put process  4 to run queue
	CPU 0: Dispatched process  2
Time slot  55
libwrite: PID 2 writing value 1 to offset 1000
print_pgtbl:
 PGD=7f6d2000a1a0 P4D=7f6d18000bd0 PUD=7f6d18001be0 PMD=7f6d18002bf0
Time slot  56
	CPU 0: Processed  2 has finished
	CPU 0: Dispatched process  1
Time slot  57
Time slot  58
	CPU 0: Put process  1 to run queue
	CPU 0: Dispatched process  4
Time slot  59
Time slot  60
	CPU 0: Put process  4 to run queue
	CPU 0: Dispatched process  1
Time slot  61
Time slot  62
	CPU 0: Put process  1 to run queue
	CPU 0: Dispatched process  4
Time slot  63
Time slot  64
	CPU 0: Put process  4 to run queue
	CPU 0: Dispatched process  1
Time slot  65
	CPU 0: Processed  1 has finished
	CPU 0: Dispatched process  4
Time slot  66
Time slot  67
	CPU 0: Put process  4 to run queue
	CPU 0: Dispatched process  4
Time slot  68
Time slot  69
	CPU 0: Processed  4 has finished
	CPU 0: Dispatched process  3
Time slot  70
Time slot  71
	CPU 0: Put process  3 to run queue
	CPU 0: Dispatched process  3
Time slot  72
Time slot  73
	CPU 0: Put process  3 to run queue
	CPU 0: Dispatched process  3
Time slot  74
Time slot  75
	CPU 0: Put process  3 to run queue
	CPU 0: Dispatched process  3
Time slot  76
	CPU 0: Processed  3 has finished
	CPU 0 stopped
