Time slot   0
ld_routine
Time slot   1
	Loaded a process at input/proc/p0s, PID: 1 PRIO: 130
	CPU 3: Dispatched process  1
Time slot   2
liballoc:185
print_pgtbl:
 PDG=7f0e7c007760 P4g=7f0e7c008770 PUD=7f0e7c009780 PMD=7f0e7c00a790
Time slot   3
	Loaded a process at input/proc/m0s, PID: 2 PRIO: 120
	CPU 3: Put process  1 to run queue
	CPU 3: Dispatched process  2
liballoc:185
print_pgtbl:
 PDG=7f0e7c00e240 P4g=7f0e7c00f250 PUD=7f0e7c010260 PMD=7f0e7c011270
	CPU 2: Dispatched process  1
liballoc:185
print_pgtbl:
 PDG=7f0e7c00e240 P4g=7f0e7c00f250 PUD=7f0e7c010260 PMD=7f0e7c011270
Time slot   4
liballoc:185
print_pgtbl:
 PDG=7f0e7c00e240 P4g=7f0e7c00f250 PUD=7f0e7c010260 PMD=7f0e7c011270
libfree:210
print_pgtbl:
 PDG=7f0e7c00e240 P4g=7f0e7c00f250 PUD=7f0e7c010260 PMD=7f0e7c011270
Time slot   5
	CPU 3: Put process  2 to run queue
	CPU 3: Dispatched process  2
	Loaded a process at input/proc/s1, PID: 3 PRIO: 0
	CPU 2: Put process  1 to run queue
	CPU 2: Dispatched process  3
	CPU 1: Dispatched process  1
liballoc:185
print_pgtbl:
 PDG=7f0e7c014d40 P4g=7f0e7c015d50 PUD=7f0e7c016d60 PMD=7f0e7c017d70
Time slot   6
liballoc:185
print_pgtbl:
 PDG=7f0e7c014d40 P4g=7f0e7c015d50 PUD=7f0e7c016d60 PMD=7f0e7c017d70
	Loaded a process at input/proc/p1s, PID: 4 PRIO: 15
Time slot   7
	CPU 0: Dispatched process  4
	CPU 3: Put process  2 to run queue
	CPU 3: Dispatched process  2
	CPU 2: Put process  3 to run queue
	CPU 2: Dispatched process  3
	CPU 1: Put process  1 to run queue
	CPU 1: Dispatched process  1
libread:386
print_pgtbl:
 PDG=7f0e7c01b8c0 P4g=7f0e7c01c8d0 PUD=7f0e7c01d8e0 PMD=7f0e7c01e8f0
Time slot   8
	CPU 3: Processed  2 has finished
	CPU 0: Put process  4 to run queue
	CPU 0: Dispatched process  4
Time slot   9
	Loaded a process at input/proc/s3, PID: 5 PRIO: 39
	CPU 2: Put process  3 to run queue
	CPU 2: Dispatched process  3
	CPU 1: Put process  1 to run queue
	CPU 1: Dispatched process  5
Time slot  10
	CPU 3: Dispatched process  1
libread:386
print_pgtbl:
 PDG=7f0e7c022460 P4g=7f0e7c023470 PUD=7f0e7c024480 PMD=7f0e7c025490
	Loaded a process at input/proc/s2, PID: 6 PRIO: 120
	CPU 0: Put process  4 to run queue
	CPU 0: Dispatched process  4
Time slot  11
	Loaded a process at input/proc/m1s, PID: 7 PRIO: 15
	CPU 2: Put process  3 to run queue
	CPU 2: Dispatched process  3
	CPU 1: Put process  5 to run queue
	CPU 1: Dispatched process  7
liballoc:185
print_pgtbl:
 PDG=7f0e7c02fb10 P4g=7f0e7c030b20 PUD=7f0e7c031b30 PMD=7f0e7c032b40
Time slot  12
	CPU 3: Put process  1 to run queue
	CPU 3: Dispatched process  5
	Loaded a process at input/proc/s0, PID: 8 PRIO: 38
	CPU 2: Processed  3 has finished
	CPU 2: Dispatched process  8
liballoc:185
print_pgtbl:
 PDG=7f0e7c036750 P4g=7f0e7c037760 PUD=7f0e7c038770 PMD=7f0e7c039780
Time slot  13
	CPU 0: Put process  4 to run queue
	CPU 0: Dispatched process  4
	CPU 3: Put process  5 to run queue
	CPU 3: Dispatched process  5
	CPU 1: Put process  7 to run queue
	CPU 1: Dispatched process  7
Time slot  14
	CPU 2: Put process  8 to run queue
	CPU 2: Dispatched process  8
Time slot  15
liballoc:185
print_pgtbl:
 PDG=7f0e7c036750 P4g=7f0e7c037760 PUD=7f0e7c038770 PMD=7f0e7c039780
	CPU 0: Put process  4 to run queue
	CPU 0: Dispatched process  4
Time slot  16
	CPU 1: Put process  7 to run queue
	CPU 1: Dispatched process  7
libfree:210
print_pgtbl:
 PDG=7f0e7c036750 P4g=7f0e7c037760 PUD=7f0e7c038770 PMD=7f0e7c039780
	CPU 3: Put process  5 to run queue
	CPU 3: Dispatched process  5
	CPU 2: Put process  8 to run queue
	CPU 2: Dispatched process  8
libfree:210
print_pgtbl:
 PDG=7f0e7c036750 P4g=7f0e7c037760 PUD=7f0e7c038770 PMD=7f0e7c039780
Time slot  17
	CPU 0: Processed  4 has finished
	CPU 0: Dispatched process  6
	CPU 3: Put process  5 to run queue
	CPU 3: Dispatched process  5
	CPU 1: Processed  7 has finished
	CPU 1: Dispatched process  1
libread:386
print_pgtbl:
 PDG=7f0e7c036750 P4g=7f0e7c037760 PUD=7f0e7c038770 PMD=7f0e7c039780
Time slot  18
	CPU 2: Put process  8 to run queue
	CPU 2: Dispatched process  8
	CPU 0: Put process  6 to run queue
	CPU 0: Dispatched process  6
Time slot  19
	CPU 1: Put process  1 to run queue
	CPU 1: Dispatched process  1
Time slot  20
	CPU 3: Put process  5 to run queue
	CPU 3: Dispatched process  5
	CPU 2: Put process  8 to run queue
	CPU 2: Dispatched process  8
	CPU 0: Put process  6 to run queue
	CPU 0: Dispatched process  6
Time slot  21
	CPU 3: Processed  5 has finished
	CPU 3 stopped
	CPU 1: Processed  1 has finished
	CPU 1 stopped
Time slot  22
	CPU 2: Put process  8 to run queue
	CPU 2: Dispatched process  8
	CPU 0: Put process  6 to run queue
	CPU 0: Dispatched process  6
Time slot  23
Time slot  24
	CPU 2: Put process  8 to run queue
	CPU 2: Dispatched process  8
	CPU 0: Put process  6 to run queue
	CPU 0: Dispatched process  6
Time slot  25
Time slot  26
	CPU 2: Put process  8 to run queue
	CPU 2: Dispatched process  8
	CPU 0: Put process  6 to run queue
	CPU 0: Dispatched process  6
Time slot  27
	CPU 2: Processed  8 has finished
	CPU 2 stopped
Time slot  28
Time slot  29
	CPU 0: Processed  6 has finished
	CPU 0 stopped
