Time slot   0
ld_routine
Time slot   1
Time slot   2
Time slot   3
Time slot   4
Time slot   5
	Loaded a process at input/proc/m2s, PID: 1 PRIO: 120
Time slot   6
	CPU 3: Dispatched process  1
liballoc:185
print_pgtbl:
 PGD=7f7e24007710 P4D=7f7e1c000bd0 PUD=7f7e1c001be0 PMD=7f7e1c002bf0
liballoc:185
print_pgtbl:
 PGD=7f7e24007710 P4D=7f7e1c000bd0 PUD=7f7e1c001be0 PMD=7f7e1c002bf0
Time slot   7
	CPU 3: Put process  1 to run queue
	CPU 3: Dispatched process  1
libfree:210
print_pgtbl:
 PGD=7f7e24007710 P4D=7f7e1c000bd0 PUD=7f7e1c001be0 PMD=7f7e1c002bf0
Time slot   8
Time slot   9
	Loaded a process at input/proc/s0, PID: 2 PRIO: 38
	CPU 3: Put process  1 to run queue
	CPU 3: Dispatched process  2
Time slot  10
	CPU 0: Dispatched process  1
Time slot  11
	Loaded a process at input/proc/s3, PID: 3 PRIO: 39
	CPU 2: Dispatched process  3
	CPU 3: Put process  2 to run queue
	CPU 3: Dispatched process  2
	CPU 0: Put process  1 to run queue
	CPU 0: Dispatched process  1
Time slot  12
	CPU 2: Put process  3 to run queue
	CPU 2: Dispatched process  3
Time slot  13
Time slot  14
	CPU 3: Put process  2 to run queue
	CPU 3: Dispatched process  2
	CPU 0: Put process  1 to run queue
	CPU 0: Dispatched process  1
	Loaded a process at input/proc/m2s, PID: 4 PRIO: 15
	CPU 2: Put process  3 to run queue
	CPU 2: Dispatched process  4
liballoc:185
print_pgtbl:
 PGD=7f7e2400fa00 P4D=7f7e18000bd0 PUD=7f7e18001be0 PMD=7f7e18002bf0
Time slot  15
	CPU 1: Dispatched process  3
	CPU 3: Put process  2 to run queue
	CPU 3: Dispatched process  2
liballoc:185
print_pgtbl:
 PGD=7f7e2400fa00 P4D=7f7e18000bd0 PUD=7f7e18001be0 PMD=7f7e18002bf0
	CPU 0: Put process  1 to run queue
	CPU 0: Dispatched process  1
libfree:210
print_pgtbl:
 PGD=7f7e2400fa00 P4D=7f7e18000bd0 PUD=7f7e18001be0 PMD=7f7e18002bf0
Time slot  16
	Loaded a process at input/proc/s2, PID: 5 PRIO: 120
	CPU 2: Put process  4 to run queue
	CPU 2: Dispatched process  4
Time slot  17
	CPU 1: Put process  3 to run queue
	CPU 1: Dispatched process  3
	Loaded a process at input/proc/s1, PID: 6 PRIO: 0
	CPU 3: Put process  2 to run queue
	CPU 3: Dispatched process  6
	CPU 0: Processed  1 has finished
	CPU 0: Dispatched process  2
Time slot  18
	CPU 2: Put process  4 to run queue
	CPU 2: Dispatched process  4
Time slot  19
	CPU 1: Put process  3 to run queue
	CPU 1: Dispatched process  3
	CPU 3: Put process  6 to run queue
	CPU 3: Dispatched process  6
	CPU 0: Put process  2 to run queue
	CPU 0: Dispatched process  2
Time slot  20
	CPU 2: Put process  4 to run queue
	CPU 2: Dispatched process  4
Time slot  21
	CPU 1: Put process  3 to run queue
	CPU 1: Dispatched process  3
Time slot  22
	CPU 3: Put process  6 to run queue
	CPU 3: Dispatched process  6
	CPU 0: Put process  2 to run queue
	CPU 0: Dispatched process  2
	CPU 1: Processed  3 has finished
	CPU 1: Dispatched process  5
Time slot  23
	CPU 2: Put process  4 to run queue
	CPU 2: Dispatched process  4
Time slot  24
	CPU 3: Put process  6 to run queue
	CPU 3: Dispatched process  6
libfree:210
print_pgtbl:
 PGD=7f7e24015050 P4D=0 PUD=0 PMD=0
	CPU 0: Put process  2 to run queue
	CPU 0: Dispatched process  2
	CPU 1: Put process  5 to run queue
	CPU 1: Dispatched process  5
Time slot  25
	CPU 3: Processed  6 has finished
	CPU 3 stopped
	CPU 2: Put process  4 to run queue
	CPU 2: Dispatched process  4
	CPU 0: Processed  2 has finished
	CPU 0 stopped
Time slot  26
	CPU 1: Put process  5 to run queue
	CPU 1: Dispatched process  5
	CPU 2: Processed  4 has finished
	CPU 2 stopped
Time slot  27
Time slot  28
	CPU 1: Put process  5 to run queue
	CPU 1: Dispatched process  5
Time slot  29
Time slot  30
	CPU 1: Put process  5 to run queue
	CPU 1: Dispatched process  5
Time slot  31
Time slot  32
	CPU 1: Put process  5 to run queue
	CPU 1: Dispatched process  5
Time slot  33
Time slot  34
	CPU 1: Processed  5 has finished
	CPU 1 stopped
