Time slot   0
ld_routine
Time slot   1
	Loaded a process at input/proc/s3, PID: 1 PRIO: 3
	CPU 0: Dispatched process  1
Time slot   2
	CPU 0: Put process  1 to run queue
	CPU 0: Dispatched process  1
Time slot   3
	Loaded a process at input/proc/m2s, PID: 2 PRIO: 3
Time slot   4
	CPU 0: Put process  1 to run queue
	CPU 0: Dispatched process  2
liballoc:185
print_pgtbl:
 PGD=7f52a800a270 P4D=7f52a0000bd0 PUD=7f52a0001be0 PMD=7f52a0002bf0
Time slot   5
	Loaded a process at input/proc/s2, PID: 3 PRIO: 3
liballoc:185
print_pgtbl:
 PGD=7f52a800ce00 P4D=7f52a0004c80 PUD=7f52a0005c90 PMD=7f52a0006ca0
Time slot   6
Time slot   7
	CPU 0: Put process  2 to run queue
	CPU 0: Dispatched process  1
Time slot   8
	CPU 0: Put process  1 to run queue
	CPU 0: Dispatched process  3
Time slot   9
Time slot  10
	CPU 0: Put process  3 to run queue
	CPU 0: Dispatched process  2
Time slot  11
	Loaded a process at input/proc/m2s, PID: 4 PRIO: 2
Time slot  12
Time slot  13
	CPU 0: Put process  2 to run queue
	CPU 0: Dispatched process  4
liballoc:185
print_pgtbl:
 PGD=7f52a800f990 P4D=7f52a0008d10 PUD=7f52a0009d20 PMD=7f52a000ad30
Time slot  14
liballoc:185
print_pgtbl:
 PGD=7f52a800f990 P4D=7f52a0008d10 PUD=7f52a0009d20 PMD=7f52a000ad30
Time slot  15
	CPU 0: Put process  4 to run queue
	CPU 0: Dispatched process  4
libfree:210
print_pgtbl:
 PGD=7f52a800f990 P4D=7f52a0008d10 PUD=7f52a0009d20 PMD=7f52a000ad30
Time slot  16
	Loaded a process at input/proc/s1, PID: 5 PRIO: 0
	CPU 0: Put process  4 to run queue
	CPU 0: Dispatched process  5
Time slot  17
Time slot  18
	CPU 0: Put process  5 to run queue
	CPU 0: Dispatched process  5
Time slot  19
Time slot  20
	CPU 0: Put process  5 to run queue
	CPU 0: Dispatched process  5
Time slot  21
Time slot  22
	CPU 0: Put process  5 to run queue
	CPU 0: Dispatched process  5
Time slot  23
	CPU 0: Processed  5 has finished
	CPU 0: Dispatched process  4
Time slot  24
Time slot  25
	CPU 0: Put process  4 to run queue
	CPU 0: Dispatched process  4
Time slot  26
Time slot  27
	CPU 0: Put process  4 to run queue
	CPU 0: Dispatched process  4
Time slot  28
Time slot  29
Time slot  30
	CPU 0: Put process  4 to run queue
	CPU 0: Dispatched process  4
Time slot  31
Time slot  32
	CPU 0: Processed  4 has finished
	CPU 0: Dispatched process  1
Time slot  33
Time slot  34
	CPU 0: Put process  1 to run queue
	CPU 0: Dispatched process  3
Time slot  35
Time slot  36
	CPU 0: Put process  3 to run queue
	CPU 0: Dispatched process  2
Time slot  37
Time slot  38
	CPU 0: Put process  2 to run queue
	CPU 0: Dispatched process  1
Time slot  39
Time slot  40
	CPU 0: Put process  1 to run queue
	CPU 0: Dispatched process  3
Time slot  41
Time slot  42
	CPU 0: Put process  3 to run queue
	CPU 0: Dispatched process  2
Time slot  43
Time slot  44
	CPU 0: Put process  2 to run queue
	CPU 0: Dispatched process  1
Time slot  45
	CPU 0: Processed  1 has finished
	CPU 0: Dispatched process  3
Time slot  46
Time slot  47
	CPU 0: Put process  3 to run queue
	CPU 0: Dispatched process  2
Time slot  48
Time slot  49
	CPU 0: Put process  2 to run queue
	CPU 0: Dispatched process  3
Time slot  50
Time slot  51
	CPU 0: Put process  3 to run queue
	CPU 0: Dispatched process  2
Time slot  52
Time slot  53
	CPU 0: Processed  2 has finished
	CPU 0: Dispatched process  3
Time slot  54
Time slot  55
	CPU 0: Processed  3 has finished
	CPU 0 stopped
