Time slot   0
ld_routine
Time slot   1
Time slot   2
Time slot   3
Time slot   4
Time slot   5
	Loaded a process at input/proc/m2s, PID: 1 PRIO: 120
	CPU 3: Dispatched process  1
liballoc:185
print_pgtbl:
 PGD=7fb614007710 P4D=7fb60c000bd0 PUD=7fb60c001be0 PMD=7fb60c002bf0
Time slot   6
liballoc:185
print_pgtbl:
 PGD=7fb614007710 P4D=7fb60c000bd0 PUD=7fb60c001be0 PMD=7fb60c002bf0
Time slot   7
	CPU 3: Put process  1 to run queue
	CPU 3: Dispatched process  1
libfree:210
print_pgtbl:
 PGD=7fb614007710 P4D=7fb60c000bd0 PUD=7fb60c001be0 PMD=7fb60c002bf0
Time slot   8
	CPU 3: Put process  1 to run queue
	CPU 3: Dispatched process  1
	Loaded a process at input/proc/s0, PID: 2 PRIO: 38
	CPU 0: Dispatched process  2
Time slot   9
Time slot  10
	CPU 0: Put process  2 to run queue
	CPU 0: Dispatched process  2
Time slot  11
	CPU 3: Put process  1 to run queue
	CPU 3: Dispatched process  1
	Loaded a process at input/proc/s3, PID: 3 PRIO: 39
	CPU 2: Dispatched process  3
Time slot  12
Time slot  13
	CPU 0: Put process  2 to run queue
	CPU 0: Dispatched process  2
	CPU 3: Put process  1 to run queue
	CPU 3: Dispatched process  1
	CPU 2: Put process  3 to run queue
	CPU 2: Dispatched process  3
Time slot  14
	Loaded a process at input/proc/m2s, PID: 4 PRIO: 15
	CPU 3: Put process  1 to run queue
Time slot  15
	CPU 3: Dispatched process  1
	CPU 0: Put process  2 to run queue
	CPU 0: Dispatched process  2
	CPU 1: Dispatched process  4
liballoc:185
print_pgtbl:
 PGD=7fb61400fa00 P4D=7fb610000bd0 PUD=7fb610001be0 PMD=7fb610002bf0
	CPU 2: Put process  3 to run queue
	CPU 2: Dispatched process  3
Time slot  16
liballoc:185
print_pgtbl:
 PGD=7fb61400fa00 P4D=7fb610000bd0 PUD=7fb610001be0 PMD=7fb610002bf0
	Loaded a process at input/proc/s2, PID: 5 PRIO: 120
	CPU 0: Put process  2 to run queue
	CPU 0: Dispatched process  2
Time slot  17
	CPU 1: Put process  4 to run queue
	CPU 1: Dispatched process  4
	Loaded a process at input/proc/s1, PID: 6 PRIO: 0
	CPU 2: Put process  3 to run queue
	CPU 2: Dispatched process  6
	CPU 3: Processed  1 has finished
	CPU 3: Dispatched process  3
Time slot  18
	CPU 0: Put process  2 to run queue
	CPU 0: Dispatched process  2
Time slot  19
	CPU 2: Put process  6 to run queue
	CPU 2: Dispatched process  6
	CPU 1: Put process  4 to run queue
	CPU 1: Dispatched process  4
	CPU 3: Put process  3 to run queue
	CPU 3: Dispatched process  3
Time slot  20
	CPU 1: Put process  4 to run queue
	CPU 1: Dispatched process  4
Time slot  21
	CPU 0: Put process  2 to run queue
	CPU 0: Dispatched process  2
	CPU 2: Put process  6 to run queue
	CPU 2: Dispatched process  6
	CPU 3: Put process  3 to run queue
	CPU 3: Dispatched process  3
Time slot  22
	CPU 3: Processed  3 has finished
	CPU 3: Dispatched process  5
Time slot  23
	CPU 1: Put process  4 to run queue
	CPU 1: Dispatched process  4
	CPU 0: Put process  2 to run queue
	CPU 0: Dispatched process  2
	CPU 2: Put process  6 to run queue
	CPU 2: Dispatched process  6
Time slot  24
libfree:210
print_pgtbl:
 PGD=7fb614015050 P4D=0 PUD=0 PMD=0
	CPU 3: Put process  5 to run queue
	CPU 0: Processed  2 has finished
	CPU 3: Dispatched process  5
	CPU 0 stopped
	CPU 2: Processed  6 has finished
	CPU 2 stopped
Time slot  25
	CPU 1: Put process  4 to run queue
	CPU 1: Dispatched process  4
Time slot  26
	CPU 3: Put process  5 to run queue
	CPU 3: Dispatched process  5
Time slot  27
	CPU 1: Processed  4 has finished
	CPU 1 stopped
Time slot  28
	CPU 3: Put process  5 to run queue
	CPU 3: Dispatched process  5
Time slot  29
Time slot  30
	CPU 3: Put process  5 to run queue
	CPU 3: Dispatched process  5
Time slot  31
Time slot  32
	CPU 3: Put process  5 to run queue
	CPU 3: Dispatched process  5
Time slot  33
Time slot  34
	CPU 3: Processed  5 has finished
	CPU 3 stopped
